<?xml version="1.0" encoding="utf-8"?>
<!-- =================================================================================== -->
<!-- |    This document was autogenerated by xacro from /home/chart/devel/catkin_ws/src/eigenbot/eigenbot/urdf/autoXACRO.xacro | -->
<!-- |    EDITING THIS FILE BY HAND IS NOT RECOMMENDED                                 | -->
<!-- =================================================================================== -->
<robot name="modular_robot_compiled" xmlns:xacro="http://www.ros.org/wiki/xacro">
  <link name="fix_base"/>
  <link name="static_base_S0M0">
    <inertial>
      <!-- TODO: check this is the right offset from CAD -->
      <origin rpy="0 0 0" xyz="0 0 0.0125"/>
      <mass value=".1"/>
      <inertia ixx=".0001" ixy="0" ixz="0" iyy=".0001" iyz="0" izz=".0001"/>
    </inertial>
    <visual>
      <geometry>
        <mesh filename="package://eigenbot/meshes/EigenBot_Base_body.stl" scale="0.001 0.001 0.001"/>
      </geometry>
    </visual>
    <collision>
      <geometry>
        <mesh filename="package://eigenbot/meshes/EigenBot_Base_body.stl" scale="0.001 0.001 0.001"/>
      </geometry>
    </collision>
    <material name="">
      <color rgba="0.9 0.9 0.9 1"/>
    </material>
  </link>
  <joint name="module_0_attachment" type="fixed">
    <origin rpy="0 0 0" xyz="0 0 0"/>
    <parent link="fix_base"/>
    <child link="static_base_S0M0"/>
  </joint>
  <link name="bendy_input_S6M1">
    <inertial>
      <origin rpy="0 0 0" xyz="0 0 0.03"/>
      <mass value=".3"/>
      <inertia ixx=".0001" ixy="0" ixz="0" iyy=".0001" iyz="0" izz=".0001"/>
    </inertial>
    <visual>
      <geometry>
        <mesh filename="package://eigenbot/meshes/SnakeBaseV1R2.stl" scale="0.001 0.001 0.001"/>
      </geometry>
    </visual>
    <collision>
      <geometry>
        <mesh filename="package://eigenbot/meshes/SnakeBaseV1R2.stl" scale="0.001 0.001 0.001"/>
      </geometry>
    </collision>
    <material name="">
      <color rgba="0.9 0.9 0.9 1"/>
    </material>
  </link>
  <link name="bendy_output_S6M1">
    <inertial>
      <origin rpy="0 0 0" xyz="0 0 0.0075"/>
      <mass value=".110"/>
      <inertia ixx=".00001" ixy="0" ixz="0" iyy=".00001" iyz="0" izz=".00001"/>
    </inertial>
    <visual>
      <geometry>
        <mesh filename="package://eigenbot/meshes/SnakeRotatingV1R2.stl" scale="0.001 0.001 0.001"/>
      </geometry>
      <origin rpy="0 0 0" xyz="0 0 -0.04"/>
    </visual>
    <visual>
      <geometry>
        <mesh filename="package://eigenbot/meshes/Mounting Ring Removable_CorrectOrientation v12.stl" scale="0.001 0.001 0.001"/>
      </geometry>
      <origin rpy="0 0 0" xyz="0 0 0.0365"/>
    </visual>
    <collision>
      <geometry>
        <mesh filename="package://eigenbot/meshes/SnakeRotatingV1R2.stl" scale="0.001 0.001 0.001"/>
      </geometry>
    </collision>
    <material name="">
      <color rgba="0.9 0.9 0.9 1"/>
    </material>
  </link>
  <joint name="bendy_joint_S6M1" type="revolute">
    <parent link="bendy_input_S6M1"/>
    <child link="bendy_output_S6M1"/>
    <origin rpy="0 0 0" xyz="0 0 0.04"/>
    <axis xyz="0 1 0"/>
    <limit effort="1000.0" lower="-1.57079632679" upper="1.57079632679" velocity="2"/>
  </joint>
  <joint name="module_1_attachment" type="fixed">
    <origin rpy="0 0 3.92699081699" xyz="0 0 0.025"/>
    <parent link="static_base_S0M0"/>
    <child link="bendy_input_S6M1"/>
  </joint>
  <link name="static_elbow_S3M2">
    <inertial>
      <!-- TODO: check this is the right offset from CAD -->
      <origin rpy="0 0 0" xyz="0.025 0 0.025"/>
      <mass value=".1"/>
      <inertia ixx=".0001" ixy="0" ixz="0" iyy=".0001" iyz="0" izz=".0001"/>
    </inertial>
    <visual>
      <geometry>
        <mesh filename="package://eigenbot/meshes/EigenBotElbowV1.stl" scale="0.001 0.001 0.001"/>
      </geometry>
    </visual>
    <collision>
      <geometry>
        <mesh filename="package://eigenbot/meshes/EigenBotElbowV1.stl" scale="0.001 0.001 0.001"/>
      </geometry>
    </collision>
    <material name="">
      <color rgba="0 0 1 1"/>
    </material>
  </link>
  <joint name="module_2_attachment" type="fixed">
    <origin rpy="0 0 4.71238898038" xyz="0 0 0.0445"/>
    <parent link="bendy_output_S6M1"/>
    <child link="static_elbow_S3M2"/>
  </joint>
  <link name="static_elbow_S2M3">
    <inertial>
      <!-- TODO: check this is the right offset from CAD -->
      <origin rpy="0 0 0" xyz="0.025 0 0.025"/>
      <mass value=".1"/>
      <inertia ixx=".0001" ixy="0" ixz="0" iyy=".0001" iyz="0" izz=".0001"/>
    </inertial>
    <visual>
      <geometry>
        <mesh filename="package://eigenbot/meshes/EigenBotElbowV1.stl" scale="0.001 0.001 0.001"/>
      </geometry>
    </visual>
    <collision>
      <geometry>
        <mesh filename="package://eigenbot/meshes/EigenBotElbowV1.stl" scale="0.001 0.001 0.001"/>
      </geometry>
    </collision>
    <material name="">
      <color rgba="0 0 1 1"/>
    </material>
  </link>
  <joint name="module_3_attachment" type="fixed">
    <origin rpy="0 -1.57079632679 0" xyz="-0.031 0 0.031"/>
    <parent link="static_elbow_S3M2"/>
    <child link="static_elbow_S2M3"/>
  </joint>
</robot>
