<?xml version="1.0"?>
<robot xmlns:xacro="http://www.ros.org/wiki/xacro">

<xacro:macro name="bendy_module" params="module_label">
  
    <link name="bendy_input_${module_label}">
      <inertial>
          <origin
            xyz="0 0 0.03"
            rpy="0 0 0" />
          <mass
            value=".3" />
          <inertia
            ixx=".0001"
            ixy="0"
            ixz="0"
            iyy=".0001"
            iyz="0"
            izz=".0001" />
        </inertial>
      
        <visual>
          <geometry>
			<mesh
          filename="package://eigenbot/meshes/SnakeBaseV1R2.stl" scale="0.001 0.001 0.001"/>          </geometry>

        </visual>  
        
        <collision>
          <geometry>
			<mesh
          filename="package://eigenbot/meshes/SnakeBaseV1R2.stl"  scale="0.001 0.001 0.001"/>              </geometry>
        </collision>
        
        <material
            name="">
            <color
              rgba="0.9 0.9 0.9 1" />
         </material>  
      </link>
	  
	   <link name="bendy_output_${module_label}">
      
      <inertial>
          <origin
            xyz="0 0 0.0075"
            rpy="0 0 0" />
          <mass
            value=".110" />
          <inertia
            ixx=".00001"
            ixy="0"
            ixz="0"
            iyy=".00001"
            iyz="0"
            izz=".00001" />
        </inertial>
      
        <visual>
          <geometry>
			<mesh
          filename="package://eigenbot/meshes/SnakeRotatingV1R2.stl" scale="0.001 0.001 0.001" />         
 	  </geometry>

 	<origin
            xyz="0 0 -0.04"
            rpy="0 0 0" />
        </visual>  
        
	<visual>
          <geometry>
			<mesh
          filename="package://eigenbot/meshes/Mounting Ring Removable_CorrectOrientation v12.stl" scale="0.001 0.001 0.001" />         
 	  </geometry>

 	<origin
            xyz="0 0 0.0365"
            rpy="0 0 0" />
        </visual>  

        <collision>
          <geometry>
			<mesh
          filename="package://eigenbot/meshes/SnakeRotatingV1R2.stl" scale="0.001 0.001 0.001" />              </geometry>
        </collision>
        
        <material
            name="">
            <color
              rgba="0.9 0.9 0.9 1" />
         </material>  
      </link>
	  
	  
	  
	  
  <joint name="bendy_joint_${module_label}" type="revolute">
    <parent link="bendy_input_${module_label}"/>
    <child link="bendy_output_${module_label}"/>
    <origin xyz="0 0 0.04" rpy="0 0 0" />
    <axis xyz="0 1 0"/> 
    <limit effort="1000.0" lower="${-M_PI/2}" upper="${M_PI/2}" velocity="2"/>
  </joint>
	  
	  
    </xacro:macro>
</robot>
